<?xml version="1.0" encoding="UTF-8"?>
<testng-results skipped="0" failed="1" ignored="0" total="3" passed="2">
  <reporter-output>
  </reporter-output>
  <suite name="Maven test suite1" duration-ms="62" started-at="2020-03-12T11:54:32Z" finished-at="2020-03-12T11:54:32Z">
    <groups>
    </groups>
    <test name="AddCorporate" duration-ms="62" started-at="2020-03-12T11:54:32Z" finished-at="2020-03-12T11:54:32Z">
      <class name="packageCustomer.Customer">
        <test-method status="FAIL" signature="customer_1_Details()[pri:0, instance:packageCustomer.Customer@4f933fd1]" name="customer_1_Details" duration-ms="18" started-at="2020-03-12T11:54:32Z" finished-at="2020-03-12T11:54:32Z">
          <exception class="java.lang.AssertionError">
            <message>
              <![CDATA[null]]>
            </message>
            <full-stacktrace>
              <![CDATA[java.lang.AssertionError: null
at org.testng.Assert.fail(Assert.java:96)
at org.testng.Assert.fail(Assert.java:103)
at packageCustomer.Customer.customer_1_Details(Customer.java:11)
at sun.reflect.NativeMethodAccessorImpl.invoke0(Native Method)
at sun.reflect.NativeMethodAccessorImpl.invoke(NativeMethodAccessorImpl.java:62)
at sun.reflect.DelegatingMethodAccessorImpl.invoke(DelegatingMethodAccessorImpl.java:43)
at java.lang.reflect.Method.invoke(Method.java:498)
at org.testng.internal.MethodInvocationHelper.invokeMethod(MethodInvocationHelper.java:124)
at org.testng.internal.Invoker.invokeMethod(Invoker.java:583)
at org.testng.internal.Invoker.invokeTestMethod(Invoker.java:719)
at org.testng.internal.Invoker.invokeTestMethods(Invoker.java:989)
at org.testng.internal.TestMethodWorker.invokeTestMethods(TestMethodWorker.java:125)
at org.testng.internal.TestMethodWorker.run(TestMethodWorker.java:109)
at org.testng.TestRunner.privateRun(TestRunner.java:648)
at org.testng.TestRunner.run(TestRunner.java:505)
at org.testng.SuiteRunner.runTest(SuiteRunner.java:455)
at org.testng.SuiteRunner.runSequentially(SuiteRunner.java:450)
at org.testng.SuiteRunner.privateRun(SuiteRunner.java:415)
at org.testng.SuiteRunner.run(SuiteRunner.java:364)
at org.testng.SuiteRunnerWorker.runSuite(SuiteRunnerWorker.java:52)
at org.testng.SuiteRunnerWorker.run(SuiteRunnerWorker.java:84)
at org.testng.TestNG.runSuitesSequentially(TestNG.java:1208)
at org.testng.TestNG.runSuitesLocally(TestNG.java:1137)
at org.testng.TestNG.runSuites(TestNG.java:1049)
at org.testng.TestNG.run(TestNG.java:1017)
at org.testng.remote.AbstractRemoteTestNG.run(AbstractRemoteTestNG.java:114)
at org.testng.remote.RemoteTestNG.initAndRun(RemoteTestNG.java:251)
at org.testng.remote.RemoteTestNG.main(RemoteTestNG.java:77)
]]>
            </full-stacktrace>
          </exception> <!-- java.lang.AssertionError -->
          <reporter-output>
          </reporter-output>
        </test-method> <!-- customer_1_Details -->
        <test-method status="PASS" signature="customer_2_Details()[pri:0, instance:packageCustomer.Customer@4f933fd1]" name="customer_2_Details" duration-ms="2" started-at="2020-03-12T11:54:32Z" finished-at="2020-03-12T11:54:32Z">
          <reporter-output>
          </reporter-output>
        </test-method> <!-- customer_2_Details -->
        <test-method status="PASS" signature="customer_3_Details()[pri:0, instance:packageCustomer.Customer@4f933fd1]" name="customer_3_Details" duration-ms="1" started-at="2020-03-12T11:54:32Z" finished-at="2020-03-12T11:54:32Z">
          <reporter-output>
          </reporter-output>
        </test-method> <!-- customer_3_Details -->
      </class> <!-- packageCustomer.Customer -->
    </test> <!-- AddCorporate -->
  </suite> <!-- Maven test suite1 -->
</testng-results>
